Workbook

Sheet 제조견적서
B1: FOODING LAB.
B2: 제 조 견 적 서 | R2: 수율(로스율)
R3: 0.03
B4: =TEXT(TODAY(),"yyyy년 mm월 dd일") -> 2026년 08월 30일 | E4: 공 급 자 | F4: 등록번호 | G4: 848-88-02640 | R4: 인상율 (미적용)
F5: 상호명 | G5: 주식회사 서래바이오 | H5: 대표자명 | I5: 지종환 | R5: 0
B6: 고객사명 | D6: 귀하 | F6: 사업장주소 | G6: 경기도 화성시 효행구 정남면 신백길 102-14 | R6: 원료+부자재 인상전(set당)
F7: 업 태 | G7: 제조업, 도매 및 소매업, 정보통신업, 전문·과학 및 기술 서비스업 | R7: =IF(OR($C$14="",$C$14=0),0,($G$34+$G$43)/$C$14/(1+$R$5)) -> 1074.5105
B8: 아래와 같이 견적 합니다. | F8: 종 목 | G8: 건강보조용 액화식품, 전자상거래 소매업, 응용 소프트웨어 개발 및 공급업 | R8: 가공비(set당)
F9: 담당자 | G9: 박영주 팀장 / 010-6850-3819 | R9: =IF(OR($C$14="",$C$14=0),0,$O$43/$C$14) -> 2000
R10: 목표 공급단가 (원/set)
B11: 제 품 명 | C11: (발주) 양배추 정 600mg x 60정 | E11: 포장형태 | R11: 3800
B12: 제품분류 | C12: 과·채가공품 | E12: 내 용 량 | F12: 600 | R12: 가공비 로트 총액 (원)
B13: 제품제형 | C13: 정제 | E13: 포장단위 | F13: 60 | R13: 2000000
B14: 발주수량 | C14: 1000 | E14: 섭 취 량 | F14: 1일 1회 2정
B16: 최종 견적가 (총액 / VAT 별도) | D16: =$G$57 -> 3800000
B18: * 원재료비
B19: 원 료 명 | D19: 배합비 (%) | E19: 함 량 (mg/단위) | F19: 단 가 (원/Kg) | G19: 금 액 (원/총액) | H19: 총 사용량 (g) | I19: 표시량 (mg) | T19: 패킹단위(kg) | V19: 소요 팩수 | W19: 실구매액(원) | X19: 이론 소요액(원)
B20: 양배추추출분말 | D20: 99 | E20: =IF(D20="","",D20*$F12/100) -> 594 | F20: =IFERROR(INDEX(단가마스터!$F$6:$F$20,MATCH($B20,단가마스터!$C$6:$C$20,0)),"") -> 15000 | G20: =IF(D20="","",H20/1000*F20) -> 550638 | H20: =IF(D20="","",E20*$F13*$C14/1000*(1+$R$3)) -> 36709.2 | I20: 594 | T20: =IFERROR(INDEX(단가마스터!$E$6:$E$20,MATCH($B20,단가마스터!$C$6:$C$20,0)),"") -> 20 | V20: =IF(OR(H20="",H20=0),0,ROUNDUP(H20/1000/T20,0)) -> 2 | W20: =IF(OR(V20="",V20=0),0,V20*T20*$F20) -> 600000 | X20: =IF(OR(H20="",H20=0),0,H20*$F20/1000) -> 550638
B21: 이산화규소 | D21: 0.5 | E21: =IF(D21="","",D21*$F12/100) -> 3 | F21: =IFERROR(INDEX(단가마스터!$F$6:$F$20,MATCH($B21,단가마스터!$C$6:$C$20,0)),"") -> 4000 | G21: =IF(D21="","",H21/1000*F21) -> 741.6 | H21: =IF(D21="","",E21*$F13*$C14/1000*(1+$R$3)) -> 185.4 | I21: 3 | T21: =IFERROR(INDEX(단가마스터!$E$6:$E$20,MATCH($B21,단가마스터!$C$6:$C$20,0)),"") -> 17 | V21: =IF(OR(H21="",H21=0),0,ROUNDUP(H21/1000/T21,0)) -> 1 | W21: =IF(OR(V21="",V21=0),0,V21*T21*$F21) -> 68000 | X21: =IF(OR(H21="",H21=0),0,H21*$F21/1000) -> 741.6
B22: 스테아린산마그네슘 | D22: 0.5 | E22: =IF(D22="","",D22*$F12/100) -> 3 | F22: =IFERROR(INDEX(단가마스터!$F$6:$F$20,MATCH($B22,단가마스터!$C$6:$C$20,0)),"") -> 6100 | G22: =IF(D22="","",H22/1000*F22) -> 1130.94 | H22: =IF(D22="","",E22*$F13*$C14/1000*(1+$R$3)) -> 185.4 | I22: 3 | T22: =IFERROR(INDEX(단가마스터!$E$6:$E$20,MATCH($B22,단가마스터!$C$6:$C$20,0)),"") -> 15 | V22: =IF(OR(H22="",H22=0),0,ROUNDUP(H22/1000/T22,0)) -> 1 | W22: =IF(OR(V22="",V22=0),0,V22*T22*$F22) -> 91500 | X22: =IF(OR(H22="",H22=0),0,H22*$F22/1000) -> 1130.94
E23: =IF(D23="","",D23*$F12/100) | F23: =IFERROR(INDEX(단가마스터!$F$6:$F$20,MATCH($B23,단가마스터!$C$6:$C$20,0)),"") | G23: =IF(D23="","",H23/1000*F23) | H23: =IF(D23="","",E23*$F13*$C14/1000*(1+$R$3)) | T23: =IFERROR(INDEX(단가마스터!$E$6:$E$20,MATCH($B23,단가마스터!$C$6:$C$20,0)),"") | W23: =IF(OR(V23="",V23=0),0,V23*T23*$F23) -> 0 | X23: =IF(OR(H23="",H23=0),0,H23*$F23/1000) -> 0
E24: =IF(D24="","",D24*$F12/100) | F24: =IFERROR(INDEX(단가마스터!$F$6:$F$20,MATCH($B24,단가마스터!$C$6:$C$20,0)),"") | G24: =IF(D24="","",H24/1000*F24) | H24: =IF(D24="","",E24*$F13*$C14/1000*(1+$R$3)) | T24: =IFERROR(INDEX(단가마스터!$E$6:$E$20,MATCH($B24,단가마스터!$C$6:$C$20,0)),"") | W24: =IF(OR(V24="",V24=0),0,V24*T24*$F24) -> 0 | X24: =IF(OR(H24="",H24=0),0,H24*$F24/1000) -> 0
E25: =IF(D25="","",D25*$F12/100) | F25: =IFERROR(INDEX(단가마스터!$F$6:$F$20,MATCH($B25,단가마스터!$C$6:$C$20,0)),"") | G25: =IF(D25="","",H25/1000*F25) | H25: =IF(D25="","",E25*$F13*$C14/1000*(1+$R$3)) | T25: =IFERROR(INDEX(단가마스터!$E$6:$E$20,MATCH($B25,단가마스터!$C$6:$C$20,0)),"") | W25: =IF(OR(V25="",V25=0),0,V25*T25*$F25) -> 0 | X25: =IF(OR(H25="",H25=0),0,H25*$F25/1000) -> 0
E26: =IF(D26="","",D26*$F12/100) | F26: =IFERROR(INDEX(단가마스터!$F$6:$F$20,MATCH($B26,단가마스터!$C$6:$C$20,0)),"") | G26: =IF(D26="","",H26/1000*F26) | H26: =IF(D26="","",E26*$F13*$C14/1000*(1+$R$3)) | T26: =IFERROR(INDEX(단가마스터!$E$6:$E$20,MATCH($B26,단가마스터!$C$6:$C$20,0)),"") | W26: =IF(OR(V26="",V26=0),0,V26*T26*$F26) -> 0 | X26: =IF(OR(H26="",H26=0),0,H26*$F26/1000) -> 0
E27: =IF(D27="","",D27*$F12/100) | F27: =IFERROR(INDEX(단가마스터!$F$6:$F$20,MATCH($B27,단가마스터!$C$6:$C$20,0)),"") | G27: =IF(D27="","",H27/1000*F27) | H27: =IF(D27="","",E27*$F13*$C14/1000*(1+$R$3)) | T27: =IFERROR(INDEX(단가마스터!$E$6:$E$20,MATCH($B27,단가마스터!$C$6:$C$20,0)),"") | W27: =IF(OR(V27="",V27=0),0,V27*T27*$F27) -> 0 | X27: =IF(OR(H27="",H27=0),0,H27*$F27/1000) -> 0
E28: =IF(D28="","",D28*$F12/100) | F28: =IFERROR(INDEX(단가마스터!$F$6:$F$20,MATCH($B28,단가마스터!$C$6:$C$20,0)),"") | G28: =IF(D28="","",H28/1000*F28) | H28: =IF(D28="","",E28*$F13*$C14/1000*(1+$R$3)) | T28: =IFERROR(INDEX(단가마스터!$E$6:$E$20,MATCH($B28,단가마스터!$C$6:$C$20,0)),"") | W28: =IF(OR(V28="",V28=0),0,V28*T28*$F28) -> 0 | X28: =IF(OR(H28="",H28=0),0,H28*$F28/1000) -> 0
E29: =IF(D29="","",D29*$F12/100) | F29: =IFERROR(INDEX(단가마스터!$F$6:$F$20,MATCH($B29,단가마스터!$C$6:$C$20,0)),"") | G29: =IF(D29="","",H29/1000*F29) | H29: =IF(D29="","",E29*$F13*$C14/1000*(1+$R$3)) | T29: =IFERROR(INDEX(단가마스터!$E$6:$E$20,MATCH($B29,단가마스터!$C$6:$C$20,0)),"") | W29: =IF(OR(V29="",V29=0),0,V29*T29*$F29) -> 0 | X29: =IF(OR(H29="",H29=0),0,H29*$F29/1000) -> 0
E30: =IF(D30="","",D30*$F12/100) | F30: =IFERROR(INDEX(단가마스터!$F$6:$F$20,MATCH($B30,단가마스터!$C$6:$C$20,0)),"") | G30: =IF(D30="","",H30/1000*F30) | H30: =IF(D30="","",E30*$F13*$C14/1000*(1+$R$3)) | T30: =IFERROR(INDEX(단가마스터!$E$6:$E$20,MATCH($B30,단가마스터!$C$6:$C$20,0)),"") | W30: =IF(OR(V30="",V30=0),0,V30*T30*$F30) -> 0 | X30: =IF(OR(H30="",H30=0),0,H30*$F30/1000) -> 0
E31: =IF(D31="","",D31*$F12/100) | F31: =IFERROR(INDEX(단가마스터!$F$6:$F$20,MATCH($B31,단가마스터!$C$6:$C$20,0)),"") | G31: =IF(D31="","",H31/1000*F31) | H31: =IF(D31="","",E31*$F13*$C14/1000*(1+$R$3)) | T31: =IFERROR(INDEX(단가마스터!$E$6:$E$20,MATCH($B31,단가마스터!$C$6:$C$20,0)),"") | W31: =IF(OR(V31="",V31=0),0,V31*T31*$F31) -> 0 | X31: =IF(OR(H31="",H31=0),0,H31*$F31/1000) -> 0
E32: =IF(D32="","",D32*$F12/100) | F32: =IFERROR(INDEX(단가마스터!$F$6:$F$20,MATCH($B32,단가마스터!$C$6:$C$20,0)),"") | G32: =IF(D32="","",H32/1000*F32) | H32: =IF(D32="","",E32*$F13*$C14/1000*(1+$R$3)) | T32: =IFERROR(INDEX(단가마스터!$E$6:$E$20,MATCH($B32,단가마스터!$C$6:$C$20,0)),"") | W32: =IF(OR(V32="",V32=0),0,V32*T32*$F32) -> 0 | X32: =IF(OR(H32="",H32=0),0,H32*$F32/1000) -> 0
E33: =IF(D33="","",D33*$F12/100) | F33: =IFERROR(INDEX(단가마스터!$F$6:$F$20,MATCH($B33,단가마스터!$C$6:$C$20,0)),"") | G33: =IF(D33="","",H33/1000*F33) | H33: =IF(D33="","",E33*$F13*$C14/1000*(1+$R$3)) | T33: =IFERROR(INDEX(단가마스터!$E$6:$E$20,MATCH($B33,단가마스터!$C$6:$C$20,0)),"") | W33: =IF(OR(V33="",V33=0),0,V33*T33*$F33) -> 0 | X33: =IF(OR(H33="",H33=0),0,H33*$F33/1000) -> 0
B34: 합 계 | D34: =SUM(D20:D33) -> 100 | E34: =SUM(E20:E33) -> 600 | G34: =SUM(G20:G33) -> 552510.54 | H34: =SUM(H20:H33) -> 37080 | T34: 실구매 합계 | W34: =SUM(W20:W33) -> 759500 | X34: =SUM(X20:X33) -> 552510.54
T35: 패킹 올림 차액 | W35: =W34-X34 -> 206989.46
B36: * 부재료비 | J36: * 가공비 (인건비 포함 · 로트 총액 기준)
B37: 재 료 명 | D37: 단 가 (원) | F37: 수 량 (총) | G37: 금 액 (원/총액) | H37: 비 고 | J37: 항 목 명 | L37: 단위/규격 | M37: 수 량 | N37: 단 가 (원) | O37: 금 액 (원) | P37: 비 고
B38: 용기 + 캡 (100ml) | D38: =IFERROR(INDEX(단가마스터!$F$6:$F$20,MATCH($B38,단가마스터!$C$6:$C$20,0)),"") -> 230 | F38: =IF($C$14="",0,$C$14*IFERROR(INDEX(단가마스터!$H$6:$H$20,MATCH($B38,단가마스터!$C$6:$C$20,0)),1)) -> 1000 | G38: =IF(D38="","",D38*F38) -> 230000 | H38: 1개/set | J38: 가공비 (인건비 포함) | L38: lot | M38: 1 | N38: =$R$13 -> 2000000 | O38: =IF(M38="","",M38*N38) -> 2000000 | P38: 제조·충진·포장 인건비 포함 로트 총액
B39: 라벨 | D39: =IFERROR(INDEX(단가마스터!$F$6:$F$20,MATCH($B39,단가마스터!$C$6:$C$20,0)),"") -> 240 | F39: =IF($C$14="",0,$C$14*IFERROR(INDEX(단가마스터!$H$6:$H$20,MATCH($B39,단가마스터!$C$6:$C$20,0)),1)) -> 1000 | G39: =IF(D39="","",D39*F39) -> 240000 | H39: 1장/set · 1,000장 240,000원 | O39: =IF(M39="","",M39*N39)
B40: 실리카겔 (1g) | D40: =IFERROR(INDEX(단가마스터!$F$6:$F$20,MATCH($B40,단가마스터!$C$6:$C$20,0)),"") -> 8 | F40: =IF($C$14="",0,$C$14*IFERROR(INDEX(단가마스터!$H$6:$H$20,MATCH($B40,단가마스터!$C$6:$C$20,0)),1)) -> 1000 | G40: =IF(D40="","",D40*F40) -> 8000 | H40: 1개/set · 12,000개 단위 발주 | O40: =IF(M40="","",M40*N40)
B41: PE완충비닐 | D41: =IFERROR(INDEX(단가마스터!$F$6:$F$20,MATCH($B41,단가마스터!$C$6:$C$20,0)),"") -> 8 | F41: =IF($C$14="",0,$C$14*IFERROR(INDEX(단가마스터!$H$6:$H$20,MATCH($B41,단가마스터!$C$6:$C$20,0)),1)) -> 1000 | G41: =IF(D41="","",D41*F41) -> 8000 | H41: 1매/set · 1롤 19,000원, 20×16cm | O41: =IF(M41="","",M41*N41)
B42: 운송용카톤 | D42: =IFERROR(INDEX(단가마스터!$F$6:$F$20,MATCH($B42,단가마스터!$C$6:$C$20,0)),"") -> 1800 | F42: =IF($C$14="",0,$C$14*IFERROR(INDEX(단가마스터!$H$6:$H$20,MATCH($B42,단가마스터!$C$6:$C$20,0)),1)) -> 20 | G42: =IF(D42="","",D42*F42) -> 36000 | H42: 50입/카톤 | O42: =IF(M42="","",M42*N42)
...

Sheet 단가마스터
B2: 단가 마스터
B3: 단가는 여기서만 관리합니다. 이 표를 고치면 견적서 단가가 전부 자동으로 바뀝니다.
B5: 구 분 | C5: 품 목 명 | D5: 규 격 | E5: 패킹/최소단위 | F5: 매입단가 | G5: 최소단위 금액 | H5: set당 소요 | I5: 최종 수정일 | J5: 비 고
B6: 원료 | C6: 양배추추출분말 | D6: 분말 | E6: 20 | F6: 15000 | G6: =E6*F6 -> 300000 | I6: 46264 | J6: 20kg 패킹
B7: 원료 | C7: 스테아린산마그네슘 | D7: 분말 | E7: 15 | F7: 6100 | G7: =E7*F7 -> 91500 | I7: 46264 | J7: 15kg 패킹
B8: 원료 | C8: 이산화규소 | D8: 분말 | E8: 17 | F8: 4000 | G8: =E8*F8 -> 68000 | I8: 46264 | J8: 17kg 패킹
B9: 원료
B10: 원료
B11: 원료
B12: 원료
B13: 원료
B14: 부자재 | C14: 용기 + 캡 (100ml) | D14: 100ml 병+캡 | E14: 1 | F14: 230 | G14: =E14*F14 -> 230 | H14: 1 | I14: 46264 | J14: MOQ 확인 필요
B15: 부자재 | C15: 라벨 | D15: 1,000장 단위 | E15: 1000 | F15: 240 | G15: 240000 | H15: 1 | I15: 46264 | J15: 1,000장 240,000원
B16: 부자재 | C16: 실리카겔 (1g) | D16: 12,000개 단위 | E16: 12000 | F16: 8 | G16: 96000 | H16: 1 | I16: 46264 | J16: 잔여 재고 부담 큼
B17: 부자재 | C17: PE완충비닐 | D17: 0.03×20cm×457m | E17: 2856 | F17: 8 | G17: 19000 | H17: 1 | I17: 46264 | J17: 1롤 19,000원 / 20×16cm
B18: 부자재 | C18: 운송용카톤 | D18: 50입 | E18: 50 | F18: 1800 | G18: 1800 | H18: =1/50 -> 0.02 | I18: 46264 | J18: 50 set / 카톤
B19: 부자재
B20: 부자재
B22: 입력칸 (노란색) | C22: 품목명 · 규격 · 패킹/최소단위 · 매입단가를 여기서 수정하세요. 견적서·원가분석이 전부 자동 반영됩니다.
B23: 패킹/최소단위 | C23: 원료는 kg 단위 패킹, 부자재는 한 번에 사야 하는 최소 수량 (set 환산)
B24: 최소단위 금액 | C24: 그 최소단위를 한 번 구매할 때 나가는 실제 금액 (원가분석에 사용)
B25: set당 소요 | C25: 1 set 만들 때 들어가는 개수. 카톤은 50입이라 1/50

Sheet 원가분석
B2: 원가 분석 · 3,800원 역산
B3: 공급단가 3,800원 / set 기준. 원료·부자재는 인상율 없이 매입단가 그대로, 가공비는 로트 총액입니다.
B4: 단가는 [단가마스터] 시트에서만 수정하세요.
B6: ① 원료 실구매 원가 (패킹단위 올림) | E6: 1000 | F6: 2000 | G6: 3000
B7: 원 료 | C7: 패킹(kg) | D7: 매입단가/kg | E7: =E$6 -> 1000 | F7: =F$6 -> 2000 | G7: =G$6 -> 3000
B8: =제조견적서!$B$20 -> 양배추추출분말 | C8: =제조견적서!$T$20 -> 20 | D8: =제조견적서!$F$20 -> 15000 | E8: =IF(N($C8)=0,0,ROUNDUP(E$6*제조견적서!$D$20*제조견적서!$F$12/100*제조견적서!$F$13*(1+제조견적서!$R$3)/1000000/$C8,0)*$C8*$D8) -> 600000 | F8: =IF(N($C8)=0,0,ROUNDUP(F$6*제조견적서!$D$20*제조견적서!$F$12/100*제조견적서!$F$13*(1+제조견적서!$R$3)/1000000/$C8,0)*$C8*$D8) -> 1200000 | G8: =IF(N($C8)=0,0,ROUNDUP(G$6*제조견적서!$D$20*제조견적서!$F$12/100*제조견적서!$F$13*(1+제조견적서!$R$3)/1000000/$C8,0)*$C8*$D8) -> 1800000
B9: =제조견적서!$B$21 -> 이산화규소 | C9: =제조견적서!$T$21 -> 17 | D9: =제조견적서!$F$21 -> 4000 | E9: =IF(N($C9)=0,0,ROUNDUP(E$6*제조견적서!$D$21*제조견적서!$F$12/100*제조견적서!$F$13*(1+제조견적서!$R$3)/1000000/$C9,0)*$C9*$D9) -> 68000 | F9: =IF(N($C9)=0,0,ROUNDUP(F$6*제조견적서!$D$21*제조견적서!$F$12/100*제조견적서!$F$13*(1+제조견적서!$R$3)/1000000/$C9,0)*$C9*$D9) -> 68000 | G9: =IF(N($C9)=0,0,ROUNDUP(G$6*제조견적서!$D$21*제조견적서!$F$12/100*제조견적서!$F$13*(1+제조견적서!$R$3)/1000000/$C9,0)*$C9*$D9) -> 68000
B10: =제조견적서!$B$22 -> 스테아린산마그네슘 | C10: =제조견적서!$T$22 -> 15 | D10: =제조견적서!$F$22 -> 6100 | E10: =IF(N($C10)=0,0,ROUNDUP(E$6*제조견적서!$D$22*제조견적서!$F$12/100*제조견적서!$F$13*(1+제조견적서!$R$3)/1000000/$C10,0)*$C10*$D10) -> 91500 | F10: =IF(N($C10)=0,0,ROUNDUP(F$6*제조견적서!$D$22*제조견적서!$F$12/100*제조견적서!$F$13*(1+제조견적서!$R$3)/1000000/$C10,0)*$C10*$D10) -> 91500 | G10: =IF(N($C10)=0,0,ROUNDUP(G$6*제조견적서!$D$22*제조견적서!$F$12/100*제조견적서!$F$13*(1+제조견적서!$R$3)/1000000/$C10,0)*$C10*$D10) -> 91500
B11: 소 계 | E11: =SUM(E8:E10) -> 759500 | F11: =SUM(F8:F10) -> 1359500 | G11: =SUM(G8:G10) -> 1959500
B12: (참고) 사용량 기준 이론 원가 | E12: =SUMPRODUCT(E$6*제조견적서!$D$20:$D$22*제조견적서!$F$12/100*제조견적서!$F$13*(1+제조견적서!$R$3)/1000000,제조견적서!$F$20:$F$22) -> 552510.54 | F12: =SUMPRODUCT(F$6*제조견적서!$D$20:$D$22*제조견적서!$F$12/100*제조견적서!$F$13*(1+제조견적서!$R$3)/1000000,제조견적서!$F$20:$F$22) -> 1105021.1 | G12: =SUMPRODUCT(G$6*제조견적서!$D$20:$D$22*제조견적서!$F$12/100*제조견적서!$F$13*(1+제조견적서!$R$3)/1000000,제조견적서!$F$20:$F$22) -> 1657531.6
B13: ▲ 패킹 올림 추가 부담 | E13: =E11-E12 -> 206989.46 | F13: =F11-F12 -> 254478.92 | G13: =G11-G12 -> 301968.38 | H13: 잔여 원료 이월 가능하면 부담 감소
B15: ② 부자재 실구매 원가 (최소 발주단위)
B16: 재 료 | C16: 최소단위(set) | D16: 최소단위 금액 | E16: =E$6 -> 1000 | F16: =F$6 -> 2000 | G16: =G$6 -> 3000 | I16: set당 원가
B17: =제조견적서!$B$38 -> 용기 + 캡 (100ml) | C17: =IFERROR(INDEX(단가마스터!$E$6:$E$20,MATCH($B17,단가마스터!$C$6:$C$20,0)),"") -> 1 | D17: =IFERROR(INDEX(단가마스터!$G$6:$G$20,MATCH($B17,단가마스터!$C$6:$C$20,0)),"") -> 230 | E17: =IF(N($C17)=0,0,ROUNDUP(E$6/$C17,0)*$D17) -> 230000 | F17: =IF(N($C17)=0,0,ROUNDUP(F$6/$C17,0)*$D17) -> 460000 | G17: =IF(N($C17)=0,0,ROUNDUP(G$6/$C17,0)*$D17) -> 690000 | I17: =IFERROR(INDEX(단가마스터!$F$6:$F$20,MATCH($B17,단가마스터!$C$6:$C$20,0))*INDEX(단가마스터!$H$6:$H$20,MATCH($B17,단가마스터!$C$6:$C$20,0)),0) -> 230
B18: =제조견적서!$B$39 -> 라벨 | C18: =IFERROR(INDEX(단가마스터!$E$6:$E$20,MATCH($B18,단가마스터!$C$6:$C$20,0)),"") -> 1000 | D18: =IFERROR(INDEX(단가마스터!$G$6:$G$20,MATCH($B18,단가마스터!$C$6:$C$20,0)),"") -> 240000 | E18: =IF(N($C18)=0,0,ROUNDUP(E$6/$C18,0)*$D18) -> 240000 | F18: =IF(N($C18)=0,0,ROUNDUP(F$6/$C18,0)*$D18) -> 480000 | G18: =IF(N($C18)=0,0,ROUNDUP(G$6/$C18,0)*$D18) -> 720000 | I18: =IFERROR(INDEX(단가마스터!$F$6:$F$20,MATCH($B18,단가마스터!$C$6:$C$20,0))*INDEX(단가마스터!$H$6:$H$20,MATCH($B18,단가마스터!$C$6:$C$20,0)),0) -> 240
B19: =제조견적서!$B$40 -> 실리카겔 (1g) | C19: =IFERROR(INDEX(단가마스터!$E$6:$E$20,MATCH($B19,단가마스터!$C$6:$C$20,0)),"") -> 12000 | D19: =IFERROR(INDEX(단가마스터!$G$6:$G$20,MATCH($B19,단가마스터!$C$6:$C$20,0)),"") -> 96000 | E19: =IF(N($C19)=0,0,ROUNDUP(E$6/$C19,0)*$D19) -> 96000 | F19: =IF(N($C19)=0,0,ROUNDUP(F$6/$C19,0)*$D19) -> 96000 | G19: =IF(N($C19)=0,0,ROUNDUP(G$6/$C19,0)*$D19) -> 96000 | I19: =IFERROR(INDEX(단가마스터!$F$6:$F$20,MATCH($B19,단가마스터!$C$6:$C$20,0))*INDEX(단가마스터!$H$6:$H$20,MATCH($B19,단가마스터!$C$6:$C$20,0)),0) -> 8
B20: =제조견적서!$B$41 -> PE완충비닐 | C20: =IFERROR(INDEX(단가마스터!$E$6:$E$20,MATCH($B20,단가마스터!$C$6:$C$20,0)),"") -> 2856 | D20: =IFERROR(INDEX(단가마스터!$G$6:$G$20,MATCH($B20,단가마스터!$C$6:$C$20,0)),"") -> 19000 | E20: =IF(N($C20)=0,0,ROUNDUP(E$6/$C20,0)*$D20) -> 19000 | F20: =IF(N($C20)=0,0,ROUNDUP(F$6/$C20,0)*$D20) -> 19000 | G20: =IF(N($C20)=0,0,ROUNDUP(G$6/$C20,0)*$D20) -> 38000 | I20: =IFERROR(INDEX(단가마스터!$F$6:$F$20,MATCH($B20,단가마스터!$C$6:$C$20,0))*INDEX(단가마스터!$H$6:$H$20,MATCH($B20,단가마스터!$C$6:$C$20,0)),0) -> 8
B21: =제조견적서!$B$42 -> 운송용카톤 | C21: =IFERROR(INDEX(단가마스터!$E$6:$E$20,MATCH($B21,단가마스터!$C$6:$C$20,0)),"") -> 50 | D21: =IFERROR(INDEX(단가마스터!$G$6:$G$20,MATCH($B21,단가마스터!$C$6:$C$20,0)),"") -> 1800 | E21: =IF(N($C21)=0,0,ROUNDUP(E$6/$C21,0)*$D21) -> 36000 | F21: =IF(N($C21)=0,0,ROUNDUP(F$6/$C21,0)*$D21) -> 72000 | G21: =IF(N($C21)=0,0,ROUNDUP(G$6/$C21,0)*$D21) -> 108000 | I21: =IFERROR(INDEX(단가마스터!$F$6:$F$20,MATCH($B21,단가마스터!$C$6:$C$20,0))*INDEX(단가마스터!$H$6:$H$20,MATCH($B21,단가마스터!$C$6:$C$20,0)),0) -> 36
B22: 소 계 | E22: =SUM(E17:E21) -> 621000 | F22: =SUM(F17:F21) -> 1127000 | G22: =SUM(G17:G21) -> 1652000 | I22: =SUM(I17:I21) -> 522
B23: (참고) 수량 기준 이론 원가 | E23: =E$6*$I$22 -> 522000 | F23: =F$6*$I$22 -> 1044000 | G23: =G$6*$I$22 -> 1566000
B24: ▲ 최소 발주 추가 부담 | E24: =E22-E23 -> 99000 | F24: =F22-F23 -> 83000 | G24: =G22-G23 -> 86000 | H24: 실리카겔 12,000개 · 라벨 1,000장 단위
B26: ③ 가공비 (인건비 포함) — 로트 총액
B27: 구 분 | D27: 로트 총액 | E27: =E$6 -> 1000 | F27: =F$6 -> 2000 | G27: =G$6 -> 3000
B28: 가공비 150만원 | D28: 1500000 | E28: =$D28 -> 1500000 | F28: =$D28 -> 1500000 | G28: =$D28 -> 1500000 | H28: 로트 고정이라 수량이 늘수록 set당 가공비는 내려감
B29: 가공비 200만원 | D29: 2000000 | E29: =$D29 -> 2000000 | F29: =$D29 -> 2000000 | G29: =$D29 -> 2000000
B31: ④ 공급가 3,800원 기준 손익 — 가공비 150만원
B32: 구 분 | E32: =E$6 -> 1000 | F32: =F$6 -> 2000 | G32: =G$6 -> 3000
B33: 실제 총원가 (①+②+150만) | E33: =E11+E22+E28 -> 2880500 | F33: =F11+F22+F28 -> 3986500 | G33: =G11+G22+G28 -> 5111500
B34: 공급가 (3,800원 × 수량) | E34: =E$6*제조견적서!$R$11 -> 3800000 | F34: =F$6*제조견적서!$R$11 -> 7600000 | G34: =G$6*제조견적서!$R$11 -> 11400000
B35: 손 익 | E35: =E34-E33 -> 919500 | F35: =F34-F33 -> 3613500 | G35: =G34-G33 -> 6288500
B36: 마진율 | E36: =IF(E34=0,0,E35/E34) -> 0.24197368 | F36: =IF(F34=0,0,F35/F34) -> 0.47546053 | G36: =IF(G34=0,0,G35/G34) -> 0.55162281
B37: set당 제조원가 | E37: =E33/E$6 -> 2880.5 | F37: =F33/F$6 -> 1993.25 | G37: =G33/G$6 -> 1703.8333
B39: ⑤ 공급가 3,800원 기준 손익 — 가공비 200만원
B40: 구 분 | E40: =E$6 -> 1000 | F40: =F$6 -> 2000 | G40: =G$6 -> 3000
B41: 실제 총원가 (①+②+200만) | E41: =E11+E22+E29 -> 3380500 | F41: =F11+F22+F29 -> 4486500 | G41: =G11+G22+G29 -> 5611500
B42: 공급가 (3,800원 × 수량) | E42: =E$6*제조견적서!$R$11 -> 3800000 | F42: =F$6*제조견적서!$R$11 -> 7600000 | G42: =G$6*제조견적서!$R$11 -> 11400000
B43: 손 익 | E43: =E42-E41 -> 419500 | F43: =F42-F41 -> 3113500 | G43: =G42-G41 -> 5788500
B44: 마진율 | E44: =IF(E42=0,0,E43/E42) -> 0.11039474 | F44: =IF(F42=0,0,F43/F42) -> 0.40967105 | G44: =IF(G42=0,0,G43/G42) -> 0.50776316
B45: set당 제조원가 | E45: =E41/E$6 -> 3380.5 | F45: =F41/F$6 -> 2243.25 | G45: =G41/G$6 -> 1870.5
B47: ⑥ 역산 — 3,800원에 맞출 때 쓸 수 있는 가공비 한도
...

Sheet 사용법
B2: 서래바이오 제조 견적서 — 사용법
B4: 구 분 | C4: 내 용
B5: 입력 — 제품 | C5: 고객사명 B6 / 제품명 C11 / 제품분류 C12 / 제품제형 C13 / 발주수량 C14 ← 발주수량이 인상율을 결정
B6: 입력 — 사양 | C6: 포장형태 F11 / 내용량(mg) F12 / 포장단위(정) F13 / 섭취량 F14
B7: 입력 — 원료 | C7: 원료명 B20:B33 · 배합비(%) D20:D33 · 매입단가 L20:L33(인쇄 안 됨) · 패킹단위 K20:K33 · 표시량 I20:I33
B8: 입력 — 부재료 | C8: 재료명 B38:B42 · 매입단가 L38:L42(인쇄 안 됨) · 수량 F38:F42(=발주수량 연동, 카톤만 ÷50)
B9: 입력 — 가공비 | C9: 항목명 B47:B51 · 단위/규격 D · 수량 E(=발주수량 자동) · 단가 F → 소계 G52. 견적합계 가공비 = 소계 ÷ 발주수량
B10: 입력 — 수율 | C10: K3 수율(3%) · K5 적용 인상율(자동) · K7 인상전 set당 원료+부자재 · K9 set당 가공비 · K56:K58 구간요율 · L열 매입단가. 모두 인쇄영역 밖
B11: 자동 계산 | C11: 단가 F/D열(인상 반영) · 함량 E열 · 금액 G열(단가×수량) · 총사용량 H열 · 최종견적가(총액)
B12: 확인할 것 | C12: 배합비 합계 D34 가 100 인지 / 패킹 올림 차액(N35) 원가 반영 여부
B15: 계산식
B16: 구 분 | C16: 식
B17: 함량(mg/단위) | C17: 배합비% × 내용량 ÷ 100
B18: 금액(원) | C18: 총사용량(g) ÷ 1,000 × 단가(원/Kg) ※ 단가 = 매입단가 × (1+인상율)
B19: 총사용량(g) | C19: 함량 × 포장단위 × 발주수량 ÷ 1,000 × (1+수율)
B20: 제조원가 | C20: (원재료비 + 부재료비) × 발주수량 + 가공비 소계 = 원재료비 총액 + 부재료비 총액 + 가공비 소계
B21: 공급단가 | C21: 단가 = 매입단가 × (1 + 인상율). 금액 = 단가 × 수량
B22: 총 금액 | C22: 공급단가 × 발주수량 = 총금액 (10원 절사)
B23: 최종 견적가 | C23: (원료+부자재)×발주수량 + 인건비 → 10원 절사 (VAT 별도, 총액)
B25: 수량별 단가 추가율
B26: 발주수량 | C26: 추가율 / 공급단가
B27: 1,000 set | C27: +15% (원료·부자재 매입단가 × 1.15, 가공비 제외)
B28: 2,000 set | C28: +13% (원료·부자재 매입단가 × 1.13, 가공비 제외)
B29: 3,000 set | C29: +10% (원료·부자재 매입단가 × 1.10, 가공비 제외)
B30: 동작 | C30: 발주수량 C14 를 넣으면 K5 가 구간 요율을 자동 판정 → 원료 단가 F20:F33 과 부자재 단가 D38:D42 에 직접 곱해짐 → 금액·합계·최종 견적가까지 자동. C14 가 비면 인상율 0%. 구간 밖이면 그 이하 최대 구간(1,000 미만이면 15%). 구간 B56:B58 · 요율 K56:K58
B32: 가공비 — 확인 필요
B33: 항 목 | C33: 내 용
B34: 현재 상태 | C34: 공정별 수량(=발주수량)×단가로 소계, 발주수량으로 나눠 1 set 가공비 (=1,177원 정액)
B35: 참고 견적 실측 | C35: 참고 견적 1 set 1,177원을 공정별 역산 배분 (180/620/250/127) — 제조사 단가표 필요
B36: 받아야 할 것 | C36: 제조사 가공비 단가표 — ① 기준 단위(정당/병당/로트당) ② 최소 생산 로트 ③ 로트별 단가 차이 (로트 커지면 가공비 자체가 내려가는지)
B37: 주의 | C37: 이 값 없이 뽑은 견적은 제조원가가 과소 계상됨. 제조사 확인 전에는 확정 견적 금지
B39: 검증 기록
B40: 항 목 | C40: 값
B41: 테스트 조건 | C41: 내용량 700mg · 60정 · 배합비 97/1.5/1.5 (가배합비)
B42: 원재료비 / 부재료비 | C42: 1,000set 731.4 / 600.4 2,000set 718.7 / 589.7 3,000set 699.6 / 574.6
B43: 제조원가 | C43: 1,000set 2,508.8 2,000set 2,485.3 3,000set 2,451.2
B44: 구간 단가 | C44: 1,000set 2,500 / 2,000set 2,480 / 3,000set 2,450
B45: 최종 견적가 · 총 금액 | C45: C14=1,000 → 총액 2,508,700원 (set당 2,508.7원)
B46: 원본 시트 대조 | C46: 인상율을 금액→단가로 이동, 단가×수량=금액 검산 일치 (2026-08-30)
